Workbook

Sheet START_HERE
A1: HEALTHCARE CLAIMS ANALYSIS – EXCEL PORTFOLIO PROJECT
A2: Purpose | B2: Learn practical Excel skills using a completely fictional healthcare claims dataset. No real patient data is included.
A3: Goal | B3: By the end, you will have a GitHub-ready project showing Excel data cleaning, XLOOKUP, PivotTables, conditional formatting, and charts.
A5: DAY 1 – FILTERING, SORTING & BASIC FORMULAS
A6: 1 | B6: Open Raw_Claims. Turn the dataset into an Excel Table with Ctrl+T and confirm 'My table has headers'.
A7: 2 | B7: Filter Claim_Status to show only Denied claims.
A8: 3 | B8: Sort Billed_Amount from largest to smallest.
A9: 4 | B9: Add a new column named Outstanding_Balance. Formula: Allowed_Amount - Paid_Amount.
A10: 5 | B10: Add a new column named Days_to_Process. Formula: Processed_Date - Submission_Date. Leave blank when Processed_Date is blank.
A12: DAY 2 – XLOOKUP
A13: 6 | B13: Add Provider_Specialty to Raw_Claims using Provider_ID and the Providers sheet.
A14: 7 | B14: Add Provider_Region using Provider_ID and the Providers sheet.
A15: 8 | B15: Add CPT_Description using CPT_Code and the Code_Lookups sheet.
A17: DAY 3 – CONDITIONAL FORMATTING
A18: 9 | B18: Highlight Denied claims.
A19: 10 | B19: Apply a color scale or data bars to Outstanding_Balance.
A20: 11 | B20: Highlight claims with Days_to_Process greater than 30 days.
A22: DAY 4 – PIVOTTABLES
A23: 12 | B23: Pivot 1: Claim count by Claim_Status.
A24: 13 | B24: Pivot 2: Sum of Billed_Amount and Paid_Amount by Payer.
A25: 14 | B25: Pivot 3: Denied claim count by Denial_Reason.
A26: 15 | B26: Pivot 4: Average Days_to_Process by Provider_Specialty.
A28: DAY 5 – CHARTS & INSIGHTS
A29: 16 | B29: Create a column chart showing total billed vs. paid by payer.
A30: 17 | B30: Create a bar chart of the top denial reasons.
A31: 18 | B31: Write 3–5 business insights from your analysis on a new sheet named Findings.
A33: GITHUB DELIVERABLES
A34: A | B34: Completed Excel workbook.
A35: B | B35: Exported CSV of the cleaned claims data.
A36: C | B36: 2–3 screenshots of PivotTables/charts.
A37: D | B37: README.md explaining the project, Excel skills used, and your main findings.
A39: Important | B39: This dataset is synthetic and is for learning/portfolio use only. It is not intended for real medical billing or coding decisions.

Sheet Raw_Claims
A1: Claim_ID | B1: Patient_ID | C1: Provider_ID | D1: Service_Date | E1: CPT_Code | F1: ICD10_Code | G1: Billed_Amount | H1: Allowed_Amount | I1: Paid_Amount | J1: Claim_Status | K1: Denial_Reason | L1: Payer | M1: Prior_Auth | N1: Eligibility_Verified | O1: Submission_Date | P1: Processed_Date | Q1: Outstanding_Balance | R1: Days_to_Process | S1: Provider_Specialty
A2: CLM-1001 | B2: PT-2008 | C2: P001 | D2: 04/06/2026 | E2: 73030 | F2: M25.512 | G2: $229.11 | H2: $171.57 | I2: $92.62 | J2: Partial | K2: Column1 | L2: Blue Shield | M2: Not Required | N2: Yes | O2: 04/07/2026 | P2: 04/17/2026 | Q2: =H2-I2 -> 78.95 | R2: =IF(P2="","",P2-O2) -> 10 | S2: =_xlfn.XLOOKUP(C2,Providers!A:A,Providers!C:C,"Not Found") -> Primary Care
A3: CLM-1053 | B3: PT-2018 | C3: P005 | D3: 46056 | E3: 73721 | F3: M25.561 | G3: 1513.09 | H3: 961.11 | I3: 0 | J3: Denied | K3: Duplicate Claim | L3: Medicare | M3: Not Required | N3: Yes | O3: 46064 | P3: 46086 | Q3: =H3-I3 -> 961.11 | R3: =IF(P3="","",P3-O3) -> 22 | S3: =_xlfn.XLOOKUP(C3,Providers!A:A,Providers!C:C,"Not Found") -> Primary Care
A4: CLM-1051 | B4: PT-2034 | C4: P004 | D4: 46034 | E4: 73721 | F4: M25.551 | G4: 1315.29 | H4: 992.66 | I4: 0 | J4: Denied | K4: Medical Necessity | L4: Cigna | M4: Not Required | N4: Yes | O4: 46035 | P4: 46045 | Q4: =H4-I4 -> 992.66 | R4: =IF(P4="","",P4-O4) -> 10 | S4: =_xlfn.XLOOKUP(C4,Providers!A:A,Providers!C:C,"Not Found") -> Neurology
A5: CLM-1004 | B5: PT-2025 | C5: P002 | D5: 46094 | E5: 73030 | F5: R07.9 | G5: 307.02 | H5: 227.27 | I5: 227.27 | J5: Paid | L5: Aetna | M5: Yes | N5: Yes | O5: 46096 | P5: 46115 | Q5: =H5-I5 -> 0 | R5: =IF(P5="","",P5-O5) -> 19 | S5: =_xlfn.XLOOKUP(C5,Providers!A:A,Providers!C:C,"Not Found") -> Diagnostic Imaging
A6: CLM-1005 | B6: PT-2025 | C6: P005 | D6: 46082 | E6: 97110 | F6: R51.9 | G6: 144.42 | H6: 87.6 | I6: 87.6 | J6: Paid | L6: Blue Shield | M6: Not Required | N6: Yes | O6: 46085 | P6: 46124 | Q6: =H6-I6 -> 0 | R6: =IF(P6="","",P6-O6) -> 39 | S6: =_xlfn.XLOOKUP(C6,Providers!A:A,Providers!C:C,"Not Found") -> Primary Care
A7: CLM-1018 | B7: PT-2035 | C7: P001 | D7: 46035 | E7: 73721 | F7: R51.9 | G7: 1245.45 | H7: 846.86 | I7: 0 | J7: Denied | K7: Coding Error | L7: UnitedHealthcare | M7: Yes | N7: Yes | O7: 46042 | P7: 46063 | Q7: =H7-I7 -> 846.86 | R7: =IF(P7="","",P7-O7) -> 21 | S7: =_xlfn.XLOOKUP(C7,Providers!A:A,Providers!C:C,"Not Found") -> Primary Care
A8: CLM-1007 | B8: PT-2014 | C8: P006 | D8: 46051 | E8: 85025 | F8: M25.551 | G8: 110.77 | H8: 80.15 | I8: 80.15 | J8: Paid | L8: Cigna | M8: Yes | N8: Yes | O8: 46060 | P8: 46099 | Q8: =H8-I8 -> 0 | R8: =IF(P8="","",P8-O8) -> 39 | S8: =_xlfn.XLOOKUP(C8,Providers!A:A,Providers!C:C,"Not Found") -> Sports Medicine
A9: CLM-1008 | B9: PT-2028 | C9: P007 | D9: 46070 | E9: 73721 | F9: R51.9 | G9: 1333.1 | H9: 765.93 | I9: 765.93 | J9: Paid | L9: UnitedHealthcare | M9: Yes | N9: Yes | O9: 46073 | P9: 46121 | Q9: =H9-I9 -> 0 | R9: =IF(P9="","",P9-O9) -> 48 | S9: =_xlfn.XLOOKUP(C9,Providers!A:A,Providers!C:C,"Not Found") -> Orthopedics
A10: CLM-1009 | B10: PT-2005 | C10: P007 | D10: 46072 | E10: 85025 | F10: M54.2 | G10: 117.69 | H10: 92.08 | I10: 92.08 | J10: Paid | L10: Cigna | M10: Not Required | N10: Yes | O10: 46081 | P10: 46103 | Q10: =H10-I10 -> 0 | R10: =IF(P10="","",P10-O10) -> 22 | S10: =_xlfn.XLOOKUP(C10,Providers!A:A,Providers!C:C,"Not Found") -> Orthopedics
A11: CLM-1002 | B11: PT-2015 | C11: P001 | D11: 46095 | E11: 73721 | F11: M25.551 | G11: 1087.37 | H11: 771.06 | I11: 0 | J11: Denied | K11: Duplicate Claim | L11: Cigna | M11: Yes | N11: Yes | O11: 46102 | P11: 46128 | Q11: =H11-I11 -> 771.06 | R11: =IF(P11="","",P11-O11) -> 26 | S11: =_xlfn.XLOOKUP(C11,Providers!A:A,Providers!C:C,"Not Found") -> Primary Care
A12: CLM-1011 | B12: PT-2013 | C12: P003 | D12: 46071 | E12: 72148 | F12: M54.50 | G12: 1519 | H12: 1035.84 | I12: 1035.84 | J12: Paid | L12: Aetna | M12: No | N12: Yes | O12: 46076 | P12: 46096 | Q12: =H12-I12 -> 0 | R12: =IF(P12="","",P12-O12) -> 20 | S12: =_xlfn.XLOOKUP(C12,Providers!A:A,Providers!C:C,"Not Found") -> Orthopedics
A13: CLM-1012 | B13: PT-2016 | C13: P002 | D13: 46034 | E13: 85025 | F13: M25.561 | G13: 118.24 | H13: 82.04 | I13: 82.04 | J13: Paid | L13: Cigna | M13: Not Required | N13: Yes | O13: 46043 | P13: 46058 | Q13: =H13-I13 -> 0 | R13: =IF(P13="","",P13-O13) -> 15 | S13: =_xlfn.XLOOKUP(C13,Providers!A:A,Providers!C:C,"Not Found") -> Diagnostic Imaging
A14: CLM-1013 | B14: PT-2034 | C14: P007 | D14: 46051 | E14: 73721 | F14: M54.2 | G14: 1239.14 | H14: 906.25 | I14: 906.25 | J14: Paid | L14: Aetna | M14: Not Required | N14: Yes | O14: 46055 | P14: 46074 | Q14: =H14-I14 -> 0 | R14: =IF(P14="","",P14-O14) -> 19 | S14: =_xlfn.XLOOKUP(C14,Providers!A:A,Providers!C:C,"Not Found") -> Orthopedics
A15: CLM-1014 | B15: PT-2022 | C15: P001 | D15: 46099 | E15: 73721 | F15: M25.512 | G15: 906.11 | H15: 671.53 | I15: 671.53 | J15: Paid | L15: Medicare | M15: Yes | N15: No | O15: 46105 | P15: 46114 | Q15: =H15-I15 -> 0 | R15: =IF(P15="","",P15-O15) -> 9 | S15: =_xlfn.XLOOKUP(C15,Providers!A:A,Providers!C:C,"Not Found") -> Primary Care
A16: CLM-1020 | B16: PT-2031 | C16: P003 | D16: 46031 | E16: 70551 | F16: R51.9 | G16: 961.67 | H16: 546.56 | I16: 0 | J16: Denied | K16: Missing Prior Authorization | L16: Medicare | M16: No | N16: Yes | O16: 46035 | P16: 46077 | Q16: =H16-I16 -> 546.56 | R16: =IF(P16="","",P16-O16) -> 42 | S16: =_xlfn.XLOOKUP(C16,Providers!A:A,Providers!C:C,"Not Found") -> Orthopedics
A17: CLM-1016 | B17: PT-2007 | C17: P007 | D17: 46069 | E17: 93000 | F17: M25.551 | G17: 132.03 | H17: 98.61 | I17: 52.38 | J17: Partial | L17: Blue Shield | M17: Not Required | N17: Yes | O17: 46075 | P17: 46086 | Q17: =H17-I17 -> 46.23 | R17: =IF(P17="","",P17-O17) -> 11 | S17: =_xlfn.XLOOKUP(C17,Providers!A:A,Providers!C:C,"Not Found") -> Orthopedics
A18: CLM-1017 | B18: PT-2013 | C18: P004 | D18: 46092 | E18: 85025 | F18: R51.9 | G18: 73.75 | H18: 46.11 | I18: 46.11 | J18: Paid | L18: Aetna | M18: Yes | N18: Yes | O18: 46101 | P18: 46112 | Q18: =H18-I18 -> 0 | R18: =IF(P18="","",P18-O18) -> 11 | S18: =_xlfn.XLOOKUP(C18,Providers!A:A,Providers!C:C,"Not Found") -> Neurology
A19: CLM-1010 | B19: PT-2008 | C19: P005 | D19: 46079 | E19: 72148 | F19: M25.562 | G19: 953.08 | H19: 710.01 | I19: 0 | J19: Denied | K19: Coding Error | L19: Medicare | M19: Not Required | N19: Yes | O19: 46084 | P19: 46129 | Q19: =H19-I19 -> 710.01 | R19: =IF(P19="","",P19-O19) -> 45 | S19: =_xlfn.XLOOKUP(C19,Providers!A:A,Providers!C:C,"Not Found") -> Primary Care
A20: CLM-1019 | B20: PT-2019 | C20: P007 | D20: 46113 | E20: 85025 | F20: R51.9 | G20: 55.19 | H20: 33.6 | I20: 33.6 | J20: Paid | L20: Aetna | M20: Not Required | N20: Yes | O20: 46119 | P20: 46127 | Q20: =H20-I20 -> 0 | R20: =IF(P20="","",P20-O20) -> 8 | S20: =_xlfn.XLOOKUP(C20,Providers!A:A,Providers!C:C,"Not Found") -> Orthopedics
A21: CLM-1006 | B21: PT-2011 | C21: P008 | D21: 46072 | E21: 73030 | F21: M25.512 | G21: 330.62 | H21: 257.08 | I21: 0 | J21: Denied | K21: Timely Filing | L21: Aetna | M21: Yes | N21: Yes | O21: 46079 | P21: 46101 | Q21: =H21-I21 -> 257.08 | R21: =IF(P21="","",P21-O21) -> 22 | S21: =_xlfn.XLOOKUP(C21,Providers!A:A,Providers!C:C,"Not Found") -> Internal Medicine
A22: CLM-1021 | B22: PT-2003 | C22: P002 | D22: 46077 | E22: 97110 | F22: M54.2 | G22: 124.51 | H22: 92.56 | I22: 92.56 | J22: Paid | L22: Cigna | M22: No | N22: Yes | O22: 46082 | P22: 46116 | Q22: =H22-I22 -> 0 | R22: =IF(P22="","",P22-O22) -> 34 | S22: =_xlfn.XLOOKUP(C22,Providers!A:A,Providers!C:C,"Not Found") -> Diagnostic Imaging
A23: CLM-1022 | B23: PT-2005 | C23: P001 | D23: 46082 | E23: 70551 | F23: M25.561 | G23: 1383.87 | H23: 950.15 | I23: 950.15 | J23: Paid | L23: Cigna | M23: No | N23: Yes | O23: 46086 | P23: 46114 | Q23: =H23-I23 -> 0 | R23: =IF(P23="","",P23-O23) -> 28 | S23: =_xlfn.XLOOKUP(C23,Providers!A:A,Providers!C:C,"Not Found") -> Primary Care
A24: CLM-1023 | B24: PT-2011 | C24: P008 | D24: 46093 | E24: 73030 | F24: M54.50 | G24: 326.93 | H24: 228.77 | I24: 0 | J24: Pending | L24: Cigna | M24: Yes | N24: No | O24: 46096 | Q24: =H24-I24 -> 228.77 | R24: =IF(P24="","",P24-O24) | S24: =_xlfn.XLOOKUP(C24,Providers!A:A,Providers!C:C,"Not Found") -> Internal Medicine
A25: CLM-1024 | B25: PT-2008 | C25: P002 | D25: 46119 | E25: 72148 | F25: M54.2 | G25: 1217.67 | H25: 738.97 | I25: 738.97 | J25: Paid | L25: UnitedHealthcare | M25: Not Required | N25: Yes | O25: 46124 | P25: 46161 | Q25: =H25-I25 -> 0 | R25: =IF(P25="","",P25-O25) -> 37 | S25: =_xlfn.XLOOKUP(C25,Providers!A:A,Providers!C:C,"Not Found") -> Diagnostic Imaging
A26: CLM-1025 | B26: PT-2017 | C26: P001 | D26: 46035 | E26: 93000 | F26: M54.2 | G26: 93.97 | H26: 60.15 | I26: 60.15 | J26: Paid | L26: UnitedHealthcare | M26: No | N26: Yes | O26: 46043 | P26: 46083 | Q26: =H26-I26 -> 0 | R26: =IF(P26="","",P26-O26) -> 40 | S26: =_xlfn.XLOOKUP(C26,Providers!A:A,Providers!C:C,"Not Found") -> Primary Care
A27: CLM-1026 | B27: PT-2001 | C27: P002 | D27: 46033 | E27: 72148 | F27: M54.50 | G27: 1742.87 | H27: 1232.69 | I27: 1232.69 | J27: Paid | L27: Cigna | M27: Yes | N27: Yes | O27: 46039 | P27: 46046 | Q27: =H27-I27 -> 0 | R27: =IF(P27="","",P27-O27) -> 7 | S27: =_xlfn.XLOOKUP(C27,Providers!A:A,Providers!C:C,"Not Found") -> Diagnostic Imaging
A28: CLM-1027 | B28: PT-2014 | C28: P004 | D28: 46109 | E28: 70551 | F28: R07.9 | G28: 1602.1 | H28: 1263.6 | I28: 1263.6 | J28: Paid | L28: Blue Shield | M28: Not Required | N28: Yes | O28: 46113 | P28: 46128 | Q28: =H28-I28 -> 0 | R28: =IF(P28="","",P28-O28) -> 15 | S28: =_xlfn.XLOOKUP(C28,Providers!A:A,Providers!C:C,"Not Found") -> Neurology
A29: CLM-1028 | B29: PT-2027 | C29: P001 | D29: 46046 | E29: 97110 | F29: M25.551 | G29: 196.27 | H29: 153.74 | I29: 0 | J29: Denied | K29: Missing Prior Authorization | L29: Aetna | M29: No | N29: Yes | O29: 46048 | P29: 46077 | Q29: =H29-I29 -> 153.74 | R29: =IF(P29="","",P29-O29) -> 29 | S29: =_xlfn.XLOOKUP(C29,Providers!A:A,Providers!C:C,"Not Found") -> Primary Care
A30: CLM-1029 | B30: PT-2031 | C30: P004 | D30: 46049 | E30: 85025 | F30: R07.9 | G30: 64.42 | H30: 49.26 | I30: 49.26 | J30: Paid | L30: Cigna | M30: Yes | N30: Yes | O30: 46056 | P30: 46082 | Q30: =H30-I30 -> 0 | R30: =IF(P30="","",P30-O30) -> 26 | S30: =_xlfn.XLOOKUP(C30,Providers!A:A,Providers!C:C,"Not Found") -> Neurology
A31: CLM-1030 | B31: PT-2005 | C31: P005 | D31: 46068 | E31: 93000 | F31: R07.9 | G31: 174.53 | H31: 101.43 | I31: 0 | J31: Pending | L31: Aetna | M31: Yes | N31: Yes | O31: 46073 | Q31: =H31-I31 -> 101.43 | R31: =IF(P31="","",P31-O31) | S31: =_xlfn.XLOOKUP(C31,Providers!A:A,Providers!C:C,"Not Found") -> Primary Care
A32: CLM-1031 | B32: PT-2007 | C32: P007 | D32: 46068 | E32: 97110 | F32: M25.551 | G32: 172.75 | H32: 118.87 | I32: 118.87 | J32: Paid | L32: Aetna | M32: Not Required | N32: Yes | O32: 46069 | P32: 46101 | Q32: =H32-I32 -> 0 | R32: =IF(P32="","",P32-O32) -> 32 | S32: =_xlfn.XLOOKUP(C32,Providers!A:A,Providers!C:C,"Not Found") -> Orthopedics
A33: CLM-1032 | B33: PT-2034 | C33: P004 | D33: 46070 | E33: 93000 | F33: M25.561 | G33: 175.4 | H33: 140.08 | I33: 94.4 | J33: Partial | L33: Cigna | M33: Not Required | N33: Yes | O33: 46075 | P33: 46112 | Q33: =H33-I33 -> 45.68 | R33: =IF(P33="","",P33-O33) -> 37 | S33: =_xlfn.XLOOKUP(C33,Providers!A:A,Providers!C:C,"Not Found") -> Neurology
A34: CLM-1033 | B34: PT-2027 | C34: P006 | D34: 46075 | E34: 73030 | F34: R51.9 | G34: 222.2 | H34: 162.1 | I34: 162.1 | J34: Paid | L34: Medicare | M34: Not Required | N34: No | O34: 46080 | P34: 46110 | Q34: =H34-I34 -> 0 | R34: =IF(P34="","",P34-O34) -> 30 | S34: =_xlfn.XLOOKUP(C34,Providers!A:A,Providers!C:C,"Not Found") -> Sports Medicine
A35: CLM-1034 | B35: PT-2001 | C35: P005 | D35: 46060 | E35: 73721 | F35: M25.551 | G35: 1567.9 | H35: 1119.16 | I35: 1119.16 | J35: Paid | L35: UnitedHealthcare | M35: No | N35: Yes | O35: 46064 | P35: 46101 | Q35: =H35-I35 -> 0 | R35: =IF(P35="","",P35-O35) -> 37 | S35: =_xlfn.XLOOKUP(C35,Providers!A:A,Providers!C:C,"Not Found") -> Primary Care
A36: CLM-1035 | B36: PT-2011 | C36: P002 | D36: 46060 | E36: 97110 | F36: M25.561 | G36: 198.21 | H36: 149.21 | I36: 62.12 | J36: Partial | L36: UnitedHealthcare | M36: Yes | N36: Yes | O36: 46061 | P36: 46081 | Q36: =H36-I36 -> 87.09 | R36: =IF(P36="","",P36-O36) -> 20 | S36: =_xlfn.XLOOKUP(C36,Providers!A:A,Providers!C:C,"Not Found") -> Diagnostic Imaging
A37: CLM-1036 | B37: PT-2005 | C37: P008 | D37: 46077 | E37: 73721 | F37: M25.551 | G37: 1320.22 | H37: 813.09 | I37: 599.41 | J37: Partial | L37: Blue Shield | M37: Yes | N37: Yes | O37: 46079 | P37: 46111 | Q37: =H37-I37 -> 213.68 | R37: =IF(P37="","",P37-O37) -> 32 | S37: =_xlfn.XLOOKUP(C37,Providers!A:A,Providers!C:C,"Not Found") -> Internal Medicine
A38: CLM-1037 | B38: PT-2012 | C38: P008 | D38: 46030 | E38: 73721 | F38: M25.561 | G38: 1287.99 | H38: 987.09 | I38: 767.48 | J38: Partial | L38: Medicare | M38: Not Required | N38: Yes | O38: 46038 | P38: 46082 | Q38: =H38-I38 -> 219.61 | R38: =IF(P38="","",P38-O38) -> 44 | S38: =_xlfn.XLOOKUP(C38,Providers!A:A,Providers!C:C,"Not Found") -> Internal Medicine
A39: CLM-1038 | B39: PT-2028 | C39: P008 | D39: 46044 | E39: 85025 | F39: M25.562 | G39: 60.74 | H39: 37.46 | I39: 17.14 | J39: Partial | L39: Cigna | M39: Not Required | N39: Yes | O39: 46052 | P39: 46061 | Q39: =H39-I39 -> 20.32 | R39: =IF(P39="","",P39-O39) -> 9 | S39: =_xlfn.XLOOKUP(C39,Providers!A:A,Providers!C:C,"Not Found") -> Internal Medicine
A40: CLM-1041 | B40: PT-2001 | C40: P006 | D40: 46062 | E40: 93000 | F40: M25.551 | G40: 138.44 | H40: 103.6 | I40: 0 | J40: Denied | K40: Timely Filing | L40: Aetna | M40: Yes | N40: Yes | O40: 46069 | P40: 46105 | Q40: =H40-I40 -> 103.6 | R40: =IF(P40="","",P40-O40) -> 36 | S40: =_xlfn.XLOOKUP(C40,Providers!A:A,Providers!C:C,"Not Found") -> Sports Medicine
...

Sheet Providers
A1: Provider_ID | B1: Provider_Name | C1: Specialty | D1: Region
A2: P001 | B2: Harbor Medical Group | C2: Primary Care | D2: West
A3: P002 | B3: Pacific Imaging Center | C3: Diagnostic Imaging | D3: West
A4: P003 | B4: Mesa Orthopedics | C4: Orthopedics | D4: West
A5: P004 | B5: North County Neurology | C5: Neurology | D5: West
A6: P005 | B6: Sunrise Family Health | C6: Primary Care | D6: Southwest
A7: P006 | B7: Valley Sports Medicine | C7: Sports Medicine | D7: Southwest
A8: P007 | B8: Coastal Spine Clinic | C8: Orthopedics | D8: West
A9: P008 | B9: Evergreen Internal Medicine | C9: Internal Medicine | D9: Northwest

Sheet Code_Lookups
A1: CPT_Code | B1: CPT_Description | C1: Category
A2: 99213 | B2: Established patient office visit | C2: Evaluation & Management
A3: 70551 | B3: MRI brain without contrast | C3: Diagnostic Imaging
A4: 72148 | B4: MRI lumbar spine without contrast | C4: Diagnostic Imaging
A5: 73721 | B5: MRI lower-extremity joint without contrast | C5: Diagnostic Imaging
A6: 73030 | B6: X-ray shoulder | C6: Diagnostic Imaging
A7: 97110 | B7: Therapeutic exercises | C7: Physical Therapy
A8: 93000 | B8: Electrocardiogram | C8: Cardiology
A9: 85025 | B9: Complete blood count | C9: Laboratory

Sheet Claim IDs denail of reason
A1: Claim_Status | B1: Denied
A3: Denial_Reason | B3: Count of Claim_ID
A4: Coding Error | B4: 3
A5: Duplicate Claim | B5: 3
A6: Medical Necessity | B6: 3
A7: Missing Prior Authorization | B7: 4
A8: Timely Filing | B8: 2
A9: Grand Total | B9: 15

Sheet Billed vs Paid Amount By praye
A3: Payer | B3: Sum of Billed_Amount | C3: Sum of Paid_Amount
A4: Aetna | B4: 7218.79 | C4: 2428.67
A5: Blue Shield | B5: 4888.36 | C5: 2982.81
A6: Cigna | B6: 6628.1 | C6: 2690.47
A7: Medicare | B7: 8781.14 | C7: 2505.04
A8: UnitedHealthcare | B8: 9645.42 | C8: 3920.45
A9: Grand Total | B9: 37161.81 | C9: 14527.44

Sheet Provider Avg Days to process
A3: Provider_Specialty | B3: Average of Days_to_Process
A4: Diagnostic Imaging | B4: 19.333333
A5: Internal Medicine | B5: 26.75
A6: Neurology | B6: 23
A7: Orthopedics | B7: 26.181818
A8: Primary Care | B8: 24.0625
A9: Sports Medicine | B9: 36.25
A10: Grand Total | B10: 24.673077

Sheet Findings
A1: Healthcare Claims Analysis - Key Findings
A3: Sports Medicine had the longest average claim processing time at 36.25 days, compared with the overall average of 24.67 days.
A4: Missing Prior Authorization was the most common denial reason, with 4 of 15 denied claims.
A5: Total billed amount was $37,161.81, while total paid amount was $14,527.44, meaning about 39.1% of billed charges were paid.
A6: The gap between billed and paid amounts was $22,634.37.
A7: Diagnostic Imaging had the fastest average processing time at 19.33 days.
A9: Note: This project uses a fully synthetic healthcare claims dataset created for portfolio and learning purposes.
